CREATE OR REPLACE FUNCTION pyerror_invalid_program() RETURNS integer AS $$
# container: plc_python_shared
this is invalid python program
$$ LANGUAGE plcontainer;
CREATE OR REPLACE FUNCTION pyerror_invalid_import() RETURNS integer AS $$
# container: plc_python_shared
import invalid_package
$$ LANGUAGE plcontainer;
CREATE OR REPLACE FUNCTION pyerror_invalid_num() RETURNS integer AS $$
# container: plc_python_shared
return (float)3.4
$$ LANGUAGE plcontainer;
CREATE OR REPLACE FUNCTION pyerror_invalid_division() RETURNS integer AS $$
# container: plc_python_shared
return 1/0
$$ LANGUAGE plcontainer;
CREATE OR REPLACE FUNCTION pyerror_raise() RETURNS integer AS $$
# container: plc_python_shared
raise OverflowError
return 3
$$ LANGUAGE plcontainer;
CREATE OR REPLACE FUNCTION pyerror_argument(i integer, j integer) RETURNS integer AS $$
# container: plc_python_shared
return i+j+k
$$ LANGUAGE plcontainer;
select pyerror_invalid_program();
ERROR:  PL/Container client exception occurred:
DETAIL:  
 Cannot compile function in Python 
   File "<string>", line 4
    this is invalid python program
                         ^
SyntaxError: invalid syntax
select pyerror_invalid_import();
ERROR:  PL/Container client exception occurred:
DETAIL:  
 Exception occurred in Python during function execution 
 Traceback (most recent call last):
  File "<string>", line 4, in pyerror_invalid_import
ModuleNotFoundError: No module named 'invalid_package'
CONTEXT:  PLContainer function "pyerror_invalid_import"
select pyerror_invalid_num();
ERROR:  PL/Container client exception occurred:
DETAIL:  
 Cannot compile function in Python 
   File "<string>", line 4
    return (float)3.4
                    ^
SyntaxError: invalid syntax
select pyerror_invalid_division();
ERROR:  PL/Container client exception occurred:
DETAIL:  
 Exception occurred in Python during function execution 
 Traceback (most recent call last):
  File "<string>", line 4, in pyerror_invalid_division
ZeroDivisionError: division by zero
CONTEXT:  PLContainer function "pyerror_invalid_division"
select pyerror_raise();
ERROR:  PL/Container client exception occurred:
DETAIL:  
 Exception occurred in Python during function execution 
 Traceback (most recent call last):
  File "<string>", line 4, in pyerror_raise
OverflowError
select pyerror_argument(3,4);
ERROR:  PL/Container client exception occurred:
DETAIL:  
 Exception occurred in Python during function execution 
 Traceback (most recent call last):
  File "<string>", line 4, in pyerror_argument
NameError: name 'k' is not defined
CONTEXT:  PLContainer function "pyerror_argument"
